[2020-12-09 10:20:09,193] {taskinstance.py:670} INFO - Dependencies all met for <TaskInstance: Airflow_task.Data_from_table2 2020-12-09T02:10:00+00:00 [queued]>
[2020-12-09 10:20:09,201] {taskinstance.py:670} INFO - Dependencies all met for <TaskInstance: Airflow_task.Data_from_table2 2020-12-09T02:10:00+00:00 [queued]>
[2020-12-09 10:20:09,202] {taskinstance.py:880} INFO - 
--------------------------------------------------------------------------------
[2020-12-09 10:20:09,202] {taskinstance.py:881} INFO - Starting attempt 1 of 1
[2020-12-09 10:20:09,202] {taskinstance.py:882} INFO - 
--------------------------------------------------------------------------------
[2020-12-09 10:20:09,207] {taskinstance.py:901} INFO - Executing <Task(PythonOperator): Data_from_table2> on 2020-12-09T02:10:00+00:00
[2020-12-09 10:20:09,209] {standard_task_runner.py:54} INFO - Started process 36542 to run task
[2020-12-09 10:20:09,233] {standard_task_runner.py:77} INFO - Running: ['airflow', 'run', 'Airflow_task', 'Data_from_table2', '2020-12-09T02:10:00+00:00', '--job_id', '406', '--pool', 'default_pool', '--raw', '-sd', 'DAGS_FOLDER/server-elastic.py', '--cfg_path', '/var/folders/x0/npyjyyg15zj3krdkh0pv612w0000gn/T/tmpypm1nq8n']
[2020-12-09 10:20:09,234] {standard_task_runner.py:78} INFO - Job 406: Subtask Data_from_table2
[2020-12-09 10:20:09,261] {logging_mixin.py:112} INFO - Running %s on host %s <TaskInstance: Airflow_task.Data_from_table2 2020-12-09T02:10:00+00:00 [running]> 1.0.0.0.0.0.0.0.0.0.0.0.0.0.0.0.0.0.0.0.0.0.0.0.0.0.0.0.0.0.0.0.ip6.arpa
[2020-12-09 10:20:09,279] {logging_mixin.py:112} INFO - Error::::: FATAL:  database "test_aut" does not exist
[2020-12-09 10:20:09,279] {logging_mixin.py:112} INFO - 
[2020-12-09 10:20:09,279] {python_operator.py:114} INFO - Done. Returned value was: None
[2020-12-09 10:20:09,282] {taskinstance.py:1057} INFO - Marking task as SUCCESS.dag_id=Airflow_task, task_id=Data_from_table2, execution_date=20201209T021000, start_date=20201209T045009, end_date=20201209T045009
[2020-12-09 10:21:10,870] {local_task_job.py:102} INFO - Task exited with return code 0
