[2020-12-10 14:10:27,368] {taskinstance.py:670} INFO - Dependencies all met for <TaskInstance: Airflow_task.Data_from_table2 2020-12-10T08:35:00+00:00 [queued]>
[2020-12-10 14:10:27,379] {taskinstance.py:670} INFO - Dependencies all met for <TaskInstance: Airflow_task.Data_from_table2 2020-12-10T08:35:00+00:00 [queued]>
[2020-12-10 14:10:27,379] {taskinstance.py:880} INFO - 
--------------------------------------------------------------------------------
[2020-12-10 14:10:27,379] {taskinstance.py:881} INFO - Starting attempt 1 of 1
[2020-12-10 14:10:27,379] {taskinstance.py:882} INFO - 
--------------------------------------------------------------------------------
[2020-12-10 14:10:27,384] {taskinstance.py:901} INFO - Executing <Task(PythonOperator): Data_from_table2> on 2020-12-10T08:35:00+00:00
[2020-12-10 14:10:27,387] {standard_task_runner.py:54} INFO - Started process 75529 to run task
[2020-12-10 14:10:27,418] {standard_task_runner.py:77} INFO - Running: ['airflow', 'run', 'Airflow_task', 'Data_from_table2', '2020-12-10T08:35:00+00:00', '--job_id', '639', '--pool', 'default_pool', '--raw', '-sd', 'DAGS_FOLDER/server-elastic.py', '--cfg_path', '/var/folders/x0/npyjyyg15zj3krdkh0pv612w0000gn/T/tmp88dcyo2h']
[2020-12-10 14:10:27,419] {standard_task_runner.py:78} INFO - Job 639: Subtask Data_from_table2
[2020-12-10 14:10:27,450] {logging_mixin.py:112} INFO - Running %s on host %s <TaskInstance: Airflow_task.Data_from_table2 2020-12-10T08:35:00+00:00 [running]> 1.0.0.0.0.0.0.0.0.0.0.0.0.0.0.0.0.0.0.0.0.0.0.0.0.0.0.0.0.0.0.0.ip6.arpa
[2020-12-10 14:10:27,474] {logging_mixin.py:112} INFO - Error::::: FATAL:  database "test_aut" does not exist
[2020-12-10 14:10:27,474] {logging_mixin.py:112} INFO - 
[2020-12-10 14:10:27,474] {python_operator.py:114} INFO - Done. Returned value was: None
[2020-12-10 14:10:27,478] {taskinstance.py:1057} INFO - Marking task as SUCCESS.dag_id=Airflow_task, task_id=Data_from_table2, execution_date=20201210T083500, start_date=20201210T084027, end_date=20201210T084027
[2020-12-10 14:10:32,362] {local_task_job.py:102} INFO - Task exited with return code 0
