[2020-12-14 21:30:39,505] {taskinstance.py:670} INFO - Dependencies all met for <TaskInstance: First_DAG_for_test.print_data 2020-12-14T15:00:00+00:00 [queued]>
[2020-12-14 21:30:39,515] {taskinstance.py:670} INFO - Dependencies all met for <TaskInstance: First_DAG_for_test.print_data 2020-12-14T15:00:00+00:00 [queued]>
[2020-12-14 21:30:39,515] {taskinstance.py:880} INFO - 
--------------------------------------------------------------------------------
[2020-12-14 21:30:39,515] {taskinstance.py:881} INFO - Starting attempt 1 of 1
[2020-12-14 21:30:39,515] {taskinstance.py:882} INFO - 
--------------------------------------------------------------------------------
[2020-12-14 21:30:39,520] {taskinstance.py:901} INFO - Executing <Task(BashOperator): print_data> on 2020-12-14T15:00:00+00:00
[2020-12-14 21:30:39,522] {standard_task_runner.py:54} INFO - Started process 36873 to run task
[2020-12-14 21:30:39,554] {standard_task_runner.py:77} INFO - Running: ['airflow', 'run', 'First_DAG_for_test', 'print_data', '2020-12-14T15:00:00+00:00', '--job_id', '1238', '--pool', 'default_pool', '--raw', '-sd', 'DAGS_FOLDER/sampleDag.py', '--cfg_path', '/var/folders/x0/npyjyyg15zj3krdkh0pv612w0000gn/T/tmpf05zh5o1']
[2020-12-14 21:30:39,556] {standard_task_runner.py:78} INFO - Job 1238: Subtask print_data
[2020-12-14 21:30:39,586] {logging_mixin.py:112} INFO - Running %s on host %s <TaskInstance: First_DAG_for_test.print_data 2020-12-14T15:00:00+00:00 [running]> 153.225.168.192.in-addr.arpa
[2020-12-14 21:30:39,610] {bash_operator.py:113} INFO - Tmp dir root location: 
 /var/folders/x0/npyjyyg15zj3krdkh0pv612w0000gn/T
[2020-12-14 21:30:39,616] {bash_operator.py:134} INFO - Temporary script location: /var/folders/x0/npyjyyg15zj3krdkh0pv612w0000gn/T/airflowtmpldr1ymdv/print_dataeksab21x
[2020-12-14 21:30:39,617] {bash_operator.py:146} INFO - Running command: python3 /Users/sundarb/Desktop/print.py
[2020-12-14 21:30:39,625] {bash_operator.py:153} INFO - Output:
[2020-12-14 21:30:39,667] {bash_operator.py:157} INFO - /Users/sundarb/airflow/venv/bin/python3: can't open file '/Users/sundarb/Desktop/print.py': [Errno 2] No such file or directory
[2020-12-14 21:30:39,670] {bash_operator.py:159} INFO - Command exited with return code 2
[2020-12-14 21:30:39,675] {taskinstance.py:1150} ERROR - Bash command failed
Traceback (most recent call last):
  File "/Users/sundarb/airflow/venv/lib/python3.8/site-packages/airflow/models/taskinstance.py", line 984, in _run_raw_task
    result = task_copy.execute(context=context)
  File "/Users/sundarb/airflow/venv/lib/python3.8/site-packages/airflow/operators/bash_operator.py", line 165, in execute
    raise AirflowException("Bash command failed")
airflow.exceptions.AirflowException: Bash command failed
[2020-12-14 21:30:39,696] {taskinstance.py:1187} INFO - Marking task as FAILED. dag_id=First_DAG_for_test, task_id=print_data, execution_date=20201214T150000, start_date=20201214T160039, end_date=20201214T160039
[2020-12-14 21:30:44,523] {local_task_job.py:102} INFO - Task exited with return code 1
